Workbook

Sheet 服务BOQ-技术平台部1210
C2: 光储产品服务BOQ_GB | M2: 文件版本 | N2: V1.0 | O2: 适用标准 | P2: GB
M3: 编制 | N3: 殷述萍 | O3: 审核 | P3: 谢姚安、黄金良、尹威、杜碧松
B4: 密级：重要 | M4: 批准 | N4: 茆俊伟 | O4: 发布日期
B5: 说明：
B6: 序号 | C6: 业务场景 | D6: 业务场景细分 | E6: 产品类别 | F6: 产品型号 | G6: 服务产品 | H6: 服务产品说明 | I6: 计时单位 | J6: 数量 | K6: 项目场景工时（H) | P6: 备注
K7: 平地 | L7: 水上 | M7: 山地 | N7: 高原 | O7: 屋顶
B8: 1 | C8: 其他 | D8: 其他 | G8: 其他_在途 | H8: 前往项目地 | I8: 次 | J8: 1 | P8: 按需
B9: 2 | C9: 其他 | D9: 其他 | G9: 其他_入场 | H9: 开票、培训、PPE穿戴等 | I9: 次 | J9: 1 | K9: 2 | L9: 2 | M9: 2 | N9: 2 | O9: 2 | P9: 按需
B10: 3 | C10: 其他 | D10: 其他 | G10: 其他_离场 | H10: 垃圾清运、服务报告整理回填 | I10: 次 | J10: 1 | K10: 1 | L10: 1 | M10: 1 | N10: 1 | O10: 1 | P10: 按需
B11: 4 | C11: 运维 | D11: 整改,故障恢复 | E11: 户用分布式 | F11: SG30CX | G11: 运维_SG30CX_整机更换 | H11: SG30CX整机更换 | I11: 台 | J11: 1 | K11: 1.8 | L11: / | M11: / | N11: / | O11: 2.34
B12: 5 | C12: 运维 | D12: 整改,故障恢复 | E12: 户用分布式 | F12: SG50CX | G12: 运维_SG50CX_整机更换 | H12: SG50CX整机更换 | I12: 台 | J12: 1 | K12: 2.3 | L12: / | M12: / | N12: / | O12: 2.99
B13: 6 | C13: 运维 | D13: 整改,故障恢复 | E13: 户用分布式 | F13: SG110CX、SG110HX | G13: 运维_SG110系列_整机更换 | H13: SG110CX整机更换 | I13: 台 | J13: 1 | K13: 4.3 | L13: / | M13: / | N13: / | O13: 5.59
B14: 7 | C14: 交付 | D14: 交付 | E14: 地面-组串式 | F14: SG320HX | G14: 交付_SG320_产品调试 | H14: SG320系列逆变器并网调试服务 | I14: 台 | J14: 1 | K14: =SUM(K15:K18)+K19/10 -> 0.625 | L14: =SUM(L15:L18)+L19/10 -> 0.9 | M14: =SUM(M15:M18)+M19/10 -> 0.79 | N14: =SUM(N15:N18)+N19/10 -> 0.8175 | O14: =SUM(O15:O18)+O19/10 -> 0.795
B15: 7.1 | H15: 冷调-逆变器安装及固定检查 | I15: 台 | J15: 1 | K15: 0.1 | L15: 0.15 | M15: 0.13 | N15: 0.135 | O15: 0.13
B16: 7.2 | H16: 冷调-逆变器直流侧检查 | I16: 台 | J16: 1 | K16: 0.1 | L16: 0.15 | M16: 0.13 | N16: 0.135 | O16: 0.13
B17: 7.3 | H17: 冷调-逆变器交流侧检查 | I17: 台 | J17: 1 | K17: 0.1 | L17: 0.15 | M17: 0.13 | N17: 0.135 | O17: 0.13
B18: 7.4 | H18: 热调—初始化(含方阵内移动） | I18: 台 | J18: 1 | K18: 0.25 | L18: 0.375 | M18: 0.325 | N18: 0.3375 | O18: 0.33
B19: 7.5 | H19: 热调—数采通讯配置 | I19: 方阵 | J19: 1 | K19: 0.75 | L19: 0.75 | M19: 0.75 | N19: 0.75 | O19: 0.75
B20: 8 | C20: 运维 | D20: 运维 | E20: 地面-组串式 | F20: SG320HX/SG225HX | G20: 运维_SG320/SG225_产品预防性维护 | H20: SG320/SG225系列逆变器运维巡检服务 | I20: 台 | J20: 1 | K20: 0.333 | L20: 0.5 | M20: 0.45 | N20: 0.45 | O20: 0.5
B21: 9 | C21: 运维 | D21: 故障恢复 | E21: 地面-组串式 | F21: SG320HX | G21: 运维_SG320HX_一级故障恢复 | H21: 需6个小时以上恢复的故障，具体见故障分级明细 | I21: 项 | J21: 1 | K21: 8 | L21: =$K21*1.5 -> 12 | M21: =$K21*1.3 -> 10.4 | N21: =$K21*1.35 -> 10.8 | O21: 12 | P21: 故障分级明细见附件1
B22: 10 | C22: 运维 | D22: 故障恢复 | E22: 地面-组串式 | F22: SG320HX | G22: 运维_SG320HX_二级故障恢复 | H22: 6个小时内恢复的故障，具体见故障分级明细 | I22: 项 | J22: 1 | K22: 6 | L22: =$K22*1.5 -> 9 | M22: =$K22*1.3 -> 7.8 | N22: =$K22*1.35 -> 8.1 | O22: 9 | P22: 故障分级明细见附件1
B23: 11 | C23: 运维 | D23: 故障恢复 | E23: 地面-组串式 | F23: SG320HX | G23: 运维_SG320HX_三级故障恢复 | H23: 4个小时内能恢复的故障，具体见故障分级明细 | I23: 项 | J23: 1 | K23: 4 | L23: =$K23*1.5 -> 6 | M23: =$K23*1.3 -> 5.2 | N23: =$K23*1.35 -> 5.4 | O23: 6 | P23: 故障分级明细见附件1
B24: 12 | C24: 运维 | D24: 故障恢复 | E24: 地面-组串式 | F24: SG320HX | G24: 运维_SG320HX_四级故障恢复 | H24: 2个小时内能恢复的故障，具体见故障分级明细 | I24: 项 | J24: 1 | K24: 2 | L24: =$K24*1.5 -> 3 | M24: =$K24*1.3 -> 2.6 | N24: =$K24*1.35 -> 2.7 | O24: 3 | P24: 故障分级明细见附件1
B25: 13 | C25: 运维 | D25: 整改,故障恢复 | E25: 地面-组串式 | F25: SG320HX | G25: 整机更换_整改、维修 | H25: ≤3台产品，按4人配合作业 | I25: 台 | J25: 1 | K25: 4.8 | L25: 8.1 | M25: 7.86 | N25: 6.48 | O25: 7.5
B26: 14 | C26: 运维 | D26: 整改,故障恢复 | E26: 地面-组串式 | F26: SG320HX | G26: 整机更换_整改、维修 | H26: ＞3台产品，按4人配合作业 | I26: 台 | J26: 1 | K26: 4.8 | L26: 8.1 | M26: 7.86 | N26: 6.48 | O26: 6.2
B27: 15 | C27: 交付 | D27: 交付 | E27: 地面-集中式 | F27: 1+X | G27: 交付_1+X_产品调试 | H27: SG3300UD-MV系列逆变器并网调试服务 | I27: 台 | J27: 1 | K27: =K28+K29+K30+K31+K33+K32*3 -> 5.99 | L27: =L28+L29+L30+L31+L33+L32*3 -> 9.25 | M27: =M28+M29+M30+M31+M33+M32*3 -> 7.39 | N27: =N28+N29+N30+N31+N33+N32*3 -> 8.02 | O27: /
B28: 16.1 | H28: 冷调-设备出厂检验及安装 | I28: 台 | J28: 1 | K28: 0.4 | L28: 0.8 | M28: 0.4 | N28: 0.6 | O28: /
B29: 16.2 | H29: 冷调-开关柜 (RMU) 检查 | I29: 台 | J29: 1 | K29: 0.67 | L29: 1.2 | M29: 0.67 | N29: 1 | O29: /
B30: 16.3 | H30: 冷调-配电柜检查 | I30: 台 | J30: 1 | K30: 0.17 | L30: 0.5 | M30: 0.5 | N30: 0.5 | O30: /
B31: 16.4 | H31: 冷调-变压器检查 | I31: 台 | J31: 1 | K31: 0.58 | L31: 0.75 | M31: 0.75 | N31: 0.67 | O31: /
B32: 16.5 | H32: 冷调-SG1100UD逆变器单元检查 | I32: unit | J32: 1 | K32: 1 | L32: 1.5 | M32: 1.3 | N32: 1.35 | O32: /
B33: 16.6 | H33: 热调 | I33: 台 | J33: 1 | K33: 1.17 | L33: 1.5 | M33: 1.17 | N33: 1.2 | O33: /
B34: 17 | C34: 运维 | D34: 运维 | E34: 地面-集中式 | F34: 1+X | G34: 运维_1+X_产品预防性维护 | H34: 1+X系列逆变器运维服务 | I34: 台 | J34: 1 | K34: =SUM(K35:K62) -> 4.85 | L34: =SUM(L35:L62) -> 6.2533333 | M34: =SUM(M35:M62) -> 5.69 | N34: =SUM(N35:N62) -> 5.8916667 | O34: /
B35: 17.1 | G35: 一般检查 | H35: 1.检查警示标签完整 2.检查接地电阻 3.检查设备整体外观 | I35: 台 | J35: 1 | K35: 0.16666667 | L35: 0.25 | M35: 0.21666667 | N35: 0.225 | P35: 带电
B36: 17.2 | G36: 基础检查 | H36: 1.检查基础结构 2.检查螺栓紧固情况 | I36: 台 | J36: 1 | K36: 0.11666667 | L36: 0.175 | M36: 0.15166667 | N36: 0.1575 | P36: 带电
B37: 17.3 | G37: 检查系统状态 | H37: 1.检查内部元件和主电路是否变形或损坏。 2.检查产品内部是否有冷凝。 3.检查内部元器件是否可靠固定。 | I37: 台 | J37: 1 | K37: 0.16666667 | L37: 0.17 | M37: 0.16666667 | N37: 0.17
B38: 17.4 | G38: 外观检查 | H38: 1.检查产品外部或周围无易燃易爆物品、安装工具或其他物品。 2.检查逆变器外壳是否有腐蚀迹象。 3.检查所有外部螺栓是否紧固牢固。 4.检查门锁和铰链是否正常工作。 5.检查密封条完好，密封完好。 | I38: 台 | J38: 1 | K38: 0.16666667 | L38: 0.16666667 | M38: 0.16666667 | N38: 0.225 | P38: 带电
B39: 17.5 | G39: 检查内部组件和进/出风口的清洁度 | H39: 1.清洁逆变器内部组件的灰尘。 | I39: 台 | J39: 1 | K39: 0.12666667 | L39: 0.12666667 | M39: 0.12666667 | N39: 0.12666667
B40: 17.6 | G40: 检查内部组件和进/出风口的清洁度 | H40: 1.检查顶部进气口是否积尘。 2.检查底部出风口是否积尘。 | I40: 台 | J40: 1 | K40: 0.19 | L40: 0.19 | M40: 0.19 | N40: 0.19 | P40: 带电
B41: 17.7 | G41: 检查电缆连接 | H41: 1.检查所有电缆入口是否正确密封。 2.检查直流电缆和端子是否损坏。 3.检查所有带有金属零件的电缆接触面是否损坏。 4.检查接地电缆。 5.检查所有电缆是否正确布线且无短路。 | I41: 台 | J41: 1 | K41: 0.63333333 | L41: 0.95 | M41: 0.82333333 | N41: 0.855
...

Sheet 附件1
B2: 密级：重要
B3: 附件1：按故障恢复时长分类故障等级清单 | J3: 储能系统故障等级 | N3: 充电桩故障等级
B4: 故障等级 | C4: 1+X | D4: SG3125 | E4: SG320 | H4: 故障类别 | I4: 故障名称 | J4: 故障等级 | L4: 故障现象（名称或代码） | M4: 故障类型（器件级） | N4: 故障等级
B5: 一级故障 | C5: 模组故障处理 | D5: 模组故障处理 | E5: / | H5: LC告警故障 | I5: PCS故障 | J5: 四级故障 | L5: 电表读数异常故障 Abnormal Meter Reading Fault | M5: 主控软件异常 Master Control Software Anomaly | N5: 四级故障
B6: 一级故障 | C6: 交流不平衡故障处理 | D6: 直流开关异常处理 | E6: / | H6: LC告警故障 | I6: LC-PCS通信故障 | J6: 四级故障 | L6: 主从机通信故障 Master-Slave Communication Fault | M6: 主控软件异常 Master Control Software Anomaly | N6: 四级故障
B7: 一级故障 | C7: 硬件故障处理 | D7: 中点电位偏移处理 | E7: / | H7: LC告警故障 | I7: BSC故障 | J7: 四级故障 | L7: 离线故障 Offline Fault | M7: 设备离线 Device Offline | N7: 四级故障
B8: 一级故障 | C8: 软启动故障处理 | D8: 风扇故障处理 | E8: / | H8: LC告警故障 | I8: LC-BSC通信故障 | J8: 四级故障 | L8: 计费异常 Billing Anomaly | M8: 主控软件故障 Master Control Software Fault | N8: 四级故障
B9: 一级故障 | C9: 控制电源异常故障处理 | D9: 交流开关断开处理 | E9: / | H9: LC告警故障 | I9: 上位机通信故障 | J9: 四级故障 | L9: 主控软件异常 Master Control Software Anomaly | M9: 主控软件故障 Master Control Software Fault | N9: 四级故障
B10: 一级故障 | C10: 驱动板故障处理 | D10: 采样故障处理 | E10: / | H10: LC告警故障 | I10: 节点故障 | J10: 四级故障 | L10: 分控软件异常 Slave Control Software Anomaly | M10: 分控软件故障 Slave Control Software Fault | N10: 四级故障
B11: 一级故障 | C11: 电流不平衡3故障处理 | D11: 电流不平衡3 | E11: / | H11: LC告警故障 | I11: 系统未就绪故障 | J11: 四级故障 | L11: 功率单元软件异常 Power Unit Software Anomaly | M11: 功率单元软件故障 Power Unit Software Fault | N11: 四级故障
B12: 一级故障 | C12: 交流开关断开故障处理 | E12: / | H12: LC告警故障 | I12: 紧急停机 | J12: 四级故障 | L12: 灯版软件异常 Light Panel Software Anomal | M12: 灯板软件故障 Light Panel Software Fault | N12: 四级故障
B13: 二级故障 | C13: 中点电位偏移故障处理 | D13: 孤岛保护处理 | E13: / | H13: LC告警故障 | I13: 模拟采样故障 | J13: 四级故障 | L13: 平台&小程序异常 Platform & Mini Program Anomaly | M13: 平台&小程序故障 Light Panel Software Fault | N13: 四级故障
B14: 二级故障 | C14: 直流传感器故障处理 | D14: 逆变柜过温处理 | E14: / | H14: LC告警故障 | I14: 动力线异常故障 | J14: 四级故障 | L14: 屏幕程序异常 Screen Program Anomaly | M14: 屏幕程序故障 Screen Program Fault | N14: 四级故障
B15: 二级故障 | C15: 直流开关故障处理 | D15: 交流柜过温处理 | E15: / | H15: LC告警故障 | I15: PCS单元故障 | J15: 四级故障 | L15: TCU软件问题（优利特） TCU Software Issue (Unitech) | M15: 优利特TCU 软件故障 Screen Program Fault | N15: 四级故障
B16: 二级故障 | C16: 模块过热故障处理 | D16: PV极性反接处理 | E16: / | H16: LC告警故障 | I16: PCS告警 | J16: 四级故障 | L16: 充电主控模块软件问题 Charging Master Control Module Software Issue | M16: 充电主控软件模块 Charging Master Control Software Module | N16: 四级故障
B17: 二级故障 | C17: PMD变压器过热保护故障处理 | D17: 并机通讯故障处理 | E17: / | H17: LC告警故障 | I17: LC-PCS通信告警 | J17: 四级故障 | L17: 功率控制模块软件问题 Power Control Module Software Issue | M17: 功率控制模块软件故障 Power Control Module Software Fault | N17: 四级故障
B18: 二级故障 | C18: 本地紧急停机故障处理 | D18: 电网电压不平衡处理 | E18: / | H18: LC告警故障 | I18: BSC单元故障 | J18: 四级故障 | L18: TCU软件问题 TCU Software Issue | M18: TCU软件故障 TCU Software Fault | N18: 四级故障
B19: 二级故障 | C19: / | D19: GFDI保护处理 | E19: / | H19: LC告警故障 | I19: BSC单元告警 | J19: 四级故障 | L19: HCU软件问题 HCU Software Issue | M19: HCU软件故障 HCU Software Fault | N19: 四级故障
B20: 二级故障 | C20: / | D20: 硬件故障处理 | E20: / | H20: LC告警故障 | I20: LC-BSC通信告警 | J20: 四级故障 | L20: RCU软件问题 RCU Software Issue | M20: RCU软件故障 RCU Software Fault | N20: 四级故障
B21: 二级故障 | C21: / | D21: 直流防雷器故障处理 | E21: / | H21: LC告警故障 | I21: 节点告警 | J21: 四级故障 | L21: PCU软件问题 PCU Software Issue | M21: PCU软件故障 PCU Software Fault | N21: 四级故障
B22: 二级故障 | C22: / | D22: 模块过温处理 | E22: / | H22: LC告警故障 | I22: SOC上限1级告警 | J22: 四级故障 | L22: CCU软件问题 CCU Software Issue | M22: CUU软件故障 CUU Software Fault | N22: 四级故障
B23: 二级故障 | C23: / | D23: 绝缘阻抗低处理 | E23: / | H23: LC告警故障 | I23: SOC上限2级告警 | J23: 四级故障 | L23: PFC软件异常 PFC Software Anomaly | M23: PFC软件故障 CUU Software Fault | N23: 四级故障
B24: 二级故障 | C24: / | D24: 交流电流不平衡处理 | E24: / | H24: LC告警故障 | I24: SOC下限1级告警 | J24: 四级故障 | L24: LLC软件异常 LLC Software Anomaly | M24: LLC软件故障 LLC Software Fault | N24: 四级故障
... B70: 四级故障 | C70: 电网电压不平衡故障处理 | D70: 支路反向过流故障 | E70: 风扇告警处理 | H70: BSC告警故障 | I70: 风机供电回路故障 | J70: 三级故障 | L70: 调试屏幕失效 Debugging Screen Failure | M70: 屏幕失效 Screen Failure | N70: 四级故障
B71: 四级故障 | C71: 直流分量故障处理 | D71: 交流过电压故障 | H71: BSC告警故障 | I71: BSP主断路器断开 | J71: 三级故障 | L71: 调试充电枪失效 Debugging Charging Gun Failure | M71: 充电枪失效 Charging Gun Failure | N71: 四级故障
B72: 四级故障 | C72: 远程紧急停机故障处理 | D72: 低压门禁保护 | H72: BSC告警故障 | I72: BCP交流断路器断开 | J72: 三级故障 | L72: 急停按钮动作故障 Emergency Stop Button Operation Fault | M72: 急停按钮失效 Emergency Stop Button Failure | N72: 四级故障
B73: 四级故障 | C73: SCU主从通信错误故障处理 | D73: 交流过频故障 | H73: BSC告警故障 | I73: 消防系统一级报警 | J73: 三级故障 | L73: 交流断路器故障 AC Circuit Breaker Fault | M73: 交流断路器失效 AC Circuit Breaker Failure | N73: 四级故障
B74: 四级故障 | C74: 接地熔断器异常故障处理 | D74: 交流欠频故障 | H74: BSC告警故障 | I74: 消防系统二级报警 | J74: 三级故障 | L74: 直流母线输出接触器故障 DC Bus Output Contactor Fault | M74: 直流接触器失效 DC Contactor Failure | N74: 四级故障
B75: 四级故障 | C75: 逆变器过压故障处理 | D75: 温度异常报警 | H75: BSC告警故障 | I75: PCS气溶胶释放 | J75: 三级故障 | L75: 充电接口电子锁故障 Charging Interface Electronic Lock Fault | M75: 充电枪电子锁失效 Charging Gun Electronic Lock Failure | N75: 四级故障
B76: 四级故障 | C76: 过载保护故障处理 | D76: 交流欠压 | H76: BSC告警故障 | I76: 泄爆板动作 | J76: 三级故障 | L76: 充电机风扇故障 Charger Fan Fault | M76: 风扇失效 Fan Failure | N76: 四级故障
B77: 四级故障 | C77: 交流欠频故障处理 | D77: 交流绝缘检测通信异常 | H77: BSC告警故障 | I77: 变压器温控故障 | J77: 三级故障 | L77: 避雷器故障 Surge Arrester Fault | M77: 避雷器失效 Surge Arrester Failure | N77: 四级故障
B78: 四级故障 | C78: 交流欠压故障处理 | D78: IO-DSP通信异常 | H78: BSC告警故障 | I78: 变压器超温告警 | J78: 三级故障 | L78: 绝缘检测故障 Insulation Detection Fault | M78: 绝缘检测仪失效 Insulation Tester Failure | N78: 四级故障
B79: 四级故障 | C79: 交流过频故障处理 | D79: 逆变过压 | H79: BSC告警故障 | I79: 变压器超温跳闸 | J79: 三级故障 | L79: 直流输出接触器粘连故障 DC Output Contactor Welding Fault | M79: 直流接触器粘连 DC Contactor Welding | N79: 四级故障
B80: 四级故障 | C80: 交流过压故障处理 | D80: 接地熔断器异常 | H80: BSC告警故障 | I80: 开关盒风扇供电异常 | J80: 三级故障 | L80: 熔断器故障 Fuse Fault | M80: 熔断器失效 Fuse Failure | N80: 四级故障
B81: 四级故障 | C81: 交流过压故障处理 | D81: 支路熔丝异常 | H81: BSC告警故障 | I81: 节点故障 | J81: 三级故障 | L81: 泄放回路故障 Discharge Circuit Fault | M81: 充电模块失效 Charging Module Failure | N81: 四级故障
B82: 四级故障 | C82: 烟感故障处理 | D82: SCU主从通信异常 | H82: BSC告警故障 | I82: BSC-LC通信故障 | J82: 四级故障 | L82: 辅助电源故障 Auxiliary Power Supply Fault | M82: 辅助电源失效 Auxiliary Power Supply Failure | N82: 四级故障
... B88: 四级故障 | C88: / | D88: 交流电容故障 | H88: BSC告警故障 | I88: 辅助子设备告警 | J88: 四级故障 | L88: 门禁故障 Access Control Fault | M88: 门禁失效 Access Control Failure | N88: 四级故障
H89: BSC告警故障 | I89: 单元告警 | J89: 四级故障 | L89: 离线故障 Offline Fault | M89: 4G通信板失效 4G Communication Board Failure | N89: 四级故障
H90: BSC告警故障 | I90: 消防干节点火警 | J90: 四级故障 | L90: 主控板异常 Master Control Board Anomaly | M90: 主控板失效 Master Control Board Failure | N90: 四级故障
H91: BSC告警故障 | I91: 可燃气体检测设备通信故障 | J91: 四级故障 | L91: 分控板异常 Slave Control Board Anomaly | M91: 分控板失效 Slave Control Board Failure | N91: 四级故障
...

Sheet 服务BOQ（含在途、入场、现场服务工时、离场交接）
B2: 密级：重要 | C2: 光储产品服务BOQ_GB
B3: 序号 | C3: 产品类别 | D3: 产品型号 | E3: 服务项目 | F3: 服务类型 | H3: 服务项目说明 | I3: 计时单位 | J3: 数量 | K3: 在途 （单程耗时） 根据服务半径考虑路程费，不单独计算工时 | L3: 入场办理 （含开票、培训、PPE穿戴、现场断电） | M3: 业务场景工时（H) | R3: 备机搬运 | S3: 离场交接 （含垃圾清运、服务报告整理回填） | T3: 业务场景总计工时（H) | Z3: 综合单价 | AE3: 备注
F4: 一级分类 | G4: 二级分类 | M4: 平地 | N4: 水上 | O4: 山地 | P4: 高原 | Q4: 屋顶 | T4: 平地 | U4: 水上 | V4: 山地 | W4: 高原 | X4: 屋顶 | Y4: 标准公式单价 | Z4: 平地 | AA4: 水上 | AB4: 山地 | AC4: 高原 | AD4: 屋顶
B5: =ROW()-4 -> 1 | C5: 户用分布式 | D5: SG30HX | E5: 整机更换_整改、维修 | F5: 运维,整改 | G5: 维修,整改 | H5: SG30系列整机更换，按2人配合作业 | I5: 台 | J5: 1 | K5: 4 | L5: 已在业务场景工时中核算 | M5: 1.8 | N5: 2.7 | O5: 2.34 | P5: 2.43 | Q5: 2.34 | R5: 已在业务场景工时中核算 | S5: 1 | T5: =SUM($K5:$L5,$R5:$S5)+M5 -> 6.8 | U5: =SUM($K5:$L5,$R5:$S5)+N5 -> 7.7 | V5: =SUM($K5:$L5,$R5:$S5)+O5 -> 7.34 | W5: =SUM($K5:$L5,$R5:$S5)+P5 -> 7.43 | X5: =SUM($K5:$L5,$R5:$S5)+Q5 -> 7.34 | Y5: 81.25 | Z5: =T5*$Y$5 -> 552.5 | AA5: =U5*$Y$5 -> 625.625 | AB5: =V5*$Y$5 -> 596.375 | AC5: =W5*$Y$5 -> 603.6875 | AD5: =X5*$Y$5 -> 596.375
B6: =ROW()-4 -> 2 | C6: 户用分布式 | D6: SG50HX | E6: 整机更换_整改、维修 | F6: 运维,整改 | G6: 维修,整改 | H6: SG50系列整机更换，按2人配合作业 | I6: 台 | J6: 1 | K6: 4 | L6: 已在业务场景工时中核算 | M6: 2.3 | N6: 3.45 | O6: 2.99 | P6: 3.105 | Q6: 2.99 | R6: 已在业务场景工时中核算 | S6: 1 | T6: =SUM($K6:$L6,$R6:$S6)+M6 -> 7.3 | U6: =SUM($K6:$L6,$R6:$S6)+N6 -> 8.45 | V6: =SUM($K6:$L6,$R6:$S6)+O6 -> 7.99 | W6: =SUM($K6:$L6,$R6:$S6)+P6 -> 8.105 | X6: =SUM($K6:$L6,$R6:$S6)+Q6 -> 7.99 | Y6: 81.25 | Z6: =T6*$Y$5 -> 593.125 | AA6: =U6*$Y$5 -> 686.5625 | AB6: =V6*$Y$5 -> 649.1875 | AC6: =W6*$Y$5 -> 658.53125 | AD6: =X6*$Y$5 -> 649.1875
B7: =ROW()-4 -> 3 | C7: 户用分布式 | D7: SG110 | E7: 整机更换_整改、维修 | F7: 运维,整改 | G7: 维修,整改 | H7: SG110系列整机更换，按2人配合作业 | I7: 台 | J7: 1 | K7: 4 | L7: 已在业务场景工时中核算 | M7: 2.5 | N7: 3.25 | O7: 3.25 | P7: 3.375 | Q7: 3.75 | R7: 已在业务场景工时中核算 | S7: 1 | T7: =SUM($K7:$L7,$R7:$S7)+M7 -> 7.5 | U7: =SUM($K7:$L7,$R7:$S7)+N7 -> 8.25 | V7: =SUM($K7:$L7,$R7:$S7)+O7 -> 8.25 | W7: =SUM($K7:$L7,$R7:$S7)+P7 -> 8.375 | X7: =SUM($K7:$L7,$R7:$S7)+Q7 -> 8.75 | Y7: 81.25 | Z7: =T7*$Y$5 -> 609.375 | AA7: =U7*$Y$5 -> 670.3125 | AB7: =V7*$Y$5 -> 670.3125 | AC7: =W7*$Y$5 -> 680.46875 | AD7: =X7*$Y$5 -> 710.9375 | AE7: 待本周现场测算，周五前确认
B8: =ROW()-4 -> 4 | C8: 地面-组串式 | D8: SG320HX | E8: 项目交付 | F8: 交付 | G8: 交付 | H8: SG320系列逆变器并网调试服务 | I8: 台 | J8: 1 | K8: 4 | L8: 未并网交付期间，无需办理入场 | M8: 0.86 | N8: 1.29 | O8: 1.118 | P8: 1.161 | Q8: 1.118 | R8: 不涉及 | S8: 1 | T8: =SUM($K8:$L8,$R8:$S8)+M8 -> 5.86 | U8: =SUM($K8:$L8,$R8:$S8)+N8 -> 6.29 | V8: =SUM($K8:$L8,$R8:$S8)+O8 -> 6.118 | W8: =SUM($K8:$L8,$R8:$S8)+P8 -> 6.161 | X8: =SUM($K8:$L8,$R8:$S8)+Q8 -> 6.118 | Y8: 81.25 | Z8: =T8*$Y$5 -> 476.125 | AA8: =U8*$Y$5 -> 511.0625 | AB8: =V8*$Y$5 -> 497.0875 | AC8: =W8*$Y$5 -> 500.58125 | AD8: =X8*$Y$5 -> 497.0875 | AE8: 项目进度以客户需求为主、进度不可控，交付场景按人天招标
B9: =ROW()-4 -> 5 | C9: 地面-组串式 | D9: SG320HX | E9: 项目运维_巡检 | F9: 运维 | G9: 巡检 | H9: SG320系列逆变器运维巡检服务 | I9: 台 | J9: 1 | K9: 0.1 | M9: 0.333 | N9: 0.4995 | O9: 0.4329 | P9: 0.44955 | Q9: 0.4329 | R9: 不涉及 | T9: =SUM($K9:$L9,$R9:$S9)+M9 -> 0.433 | U9: =SUM($K9:$L9,$R9:$S9)+N9 -> 0.5995 | V9: =SUM($K9:$L9,$R9:$S9)+O9 -> 0.5329 | W9: =SUM($K9:$L9,$R9:$S9)+P9 -> 0.54955 | X9: =SUM($K9:$L9,$R9:$S9)+Q9 -> 0.5329 | Y9: 81.25 | Z9: =T9*$Y$5 -> 35.18125 | AA9: =U9*$Y$5 -> 48.709375 | AB9: =V9*$Y$5 -> 43.298125 | AC9: =W9*$Y$5 -> 44.650937 | AD9: =X9*$Y$5 -> 43.298125
B10: =ROW()-4 -> 6 | C10: 地面-组串式 | D10: SG320HX | E10: 一级故障恢复 | F10: 运维 | G10: 维修 | H10: 更换器件 | I10: 项 | J10: 1 | K10: 4 | L10: 4 | M10: 4 | N10: =M10*1.5 -> 6 | O10: =M10*1.3 -> 5.2 | R10: 待确认是否备件/备机搬运难度 | S10: 1 | T10: =SUM($K10:$L10,$R10:$S10)+M10 -> 13 | U10: =SUM($K10:$L10,$R10:$S10)+N10 -> 15 | V10: =SUM($K10:$L10,$R10:$S10)+O10 -> 14.2 | Y10: 81.25 | Z10: =T10*$Y$5 -> 1056.25 | AA10: =U10*$Y$5 -> 1218.75 | AB10: =V10*$Y$5 -> 1153.75 | AC10: =W10*$Y$5 -> 0 | AD10: =X10*$Y$5 -> 0 | AE10: 一级故障是否要增加4H搬运时间
B11: =ROW()-4 -> 7 | C11: 地面-组串式 | D11: SG320HX | E11: 二级故障恢复 | F11: 运维 | G11: 维修 | H11: 未更换器件 | I11: 项 | J11: 1 | K11: 4 | L11: 4 | M11: 2 | N11: =M11*1.5 -> 3 | O11: =M11*1.3 -> 2.6 | S11: 1 | T11: =SUM($K11:$L11,$R11:$S11)+M11 -> 11 | U11: =SUM($K11:$L11,$R11:$S11)+N11 -> 12 | V11: =SUM($K11:$L11,$R11:$S11)+O11 -> 11.6 | Y11: 81.25 | Z11: =T11*$Y$5 -> 893.75 | AA11: =U11*$Y$5 -> 975 | AB11: =V11*$Y$5 -> 942.5 | AC11: =W11*$Y$5 -> 0 | AD11: =X11*$Y$5 -> 0 | AE11: 屋顶320是否进行维修
B12: =ROW()-4 -> 8 | C12: 地面-组串式 | D12: SG320HX | E12: 整机更换_整改、维修 | F12: 整改 | G12: 整改 | H12: ＞3台项目，按4人配合作业 | I12: 台 | J12: 1 | K12: 4 | L12: 已在业务场景工时中核算 | M12: 4.8 | N12: 8.1 | O12: 7.86 | P12: 6.48 | Q12: 7.5 | R12: 已在业务场景工时中核算 | S12: 1 | T12: =SUM($K12:$L12,$R12:$S12)+M12 -> 9.8 | U12: =SUM($K12:$L12,$R12:$S12)+N12 -> 13.1 | V12: =SUM($K12:$L12,$R12:$S12)+O12 -> 12.86 | W12: =SUM($K12:$L12,$R12:$S12)+P12 -> 11.48 | X12: =SUM($K12:$L12,$R12:$S12)+Q12 -> 12.5 | Y12: 81.25 | Z12: =T12*$Y$5 -> 796.25 | AA12: =U12*$Y$5 -> 1064.375 | AB12: =V12*$Y$5 -> 1044.875 | AC12: =W12*$Y$5 -> 932.75 | AD12: =X12*$Y$5 -> 1015.625 | AE12: 路程时间按整改每天工作量、转换成H/台 | AF12: =T12*85 -> 833
B13: =ROW()-4 -> 9 | C13: 地面-组串式 | D13: SG320HX | E13: 整机更换_整改、维修 | F13: 运维 | G13: 维修 | H13: ≤3台项目，按4人配合作业 | I13: 台 | J13: 1 | K13: 4 | L13: 4 | M13: 4.8 | N13: 8.1 | O13: 7.86 | P13: 6.48 | Q13: 7.5 | R13: 4 | S13: 1 | T13: =SUM($K13:$L13,$R13:$S13)+M13 -> 17.8 | U13: =SUM($K13:$L13,$R13:$S13)+N13 -> 21.1 | V13: =SUM($K13:$L13,$R13:$S13)+O13 -> 20.86 | W13: =SUM($K13:$L13,$R13:$S13)+P13 -> 19.48 | X13: =SUM($K13:$L13,$R13:$S13)+Q13 -> 20.5 | Y13: 81.25 | Z13: =T13*$Y$5 -> 1446.25 | AA13: =U13*$Y$5 -> 1714.375 | AB13: =V13*$Y$5 -> 1694.875 | AC13: =W13*$Y$5 -> 1582.75 | AD13: =X13*$Y$5 -> 1665.625 | AE13: 待确认备机搬运时间、或指定固定价格
B14: =ROW()-4 -> 10 | C14: 地面-组串式 | D14: SG320HX | E14: 整机更换_整改、维修 | F14: 运维,整改 | G14: 维修,整改 | H14: ＞3台项目，按4人配合作业 | I14: 台 | J14: 1 | K14: 4 | L14: 已在业务场景工时中核算 | M14: 4.8 | N14: 8.1 | O14: 7.86 | P14: 6.48 | Q14: 6.2 | R14: 已在业务场景工时中核算 | S14: 1 | T14: =SUM($K14:$L14,$R14:$S14)+M14 -> 9.8 | U14: =SUM($K14:$L14,$R14:$S14)+N14 -> 13.1 | V14: =SUM($K14:$L14,$R14:$S14)+O14 -> 12.86 | W14: =SUM($K14:$L14,$R14:$S14)+P14 -> 11.48 | X14: =SUM($K14:$L14,$R14:$S14)+Q14 -> 11.2 | Y14: 81.25 | Z14: =T14*$Y$5 -> 796.25 | AA14: =U14*$Y$5 -> 1064.375 | AB14: =V14*$Y$5 -> 1044.875 | AC14: =W14*$Y$5 -> 932.75 | AD14: =X14*$Y$5 -> 910
B15: =ROW()-4 -> 11 | C15: 地面-集中式 | D15: 1+X | E15: 项目交付 | F15: 交付 | G15: 交付 | H15: SG3300UD-MV系列逆变器并网调试服务 | I15: 台 | J15: 1 | K15: 2.86 | L15: 未并网交付期间，无需办理入场 | M15: 6.15 | N15: 9.225 | O15: 7.995 | P15: 8.3025 | Q15: / | S15: 1 | T15: =SUM($K15:$L15,$R15:$S15)+M15 -> 10.01 | U15: =SUM($K15:$L15,$R15:$S15)+N15 -> 13.085 | V15: =SUM($K15:$L15,$R15:$S15)+O15 -> 11.855 | W15: =SUM($K15:$L15,$R15:$S15)+P15 -> 12.1625 | Y15: 81.25 | Z15: =T15*$Y$5 -> 813.3125 | AA15: =U15*$Y$5 -> 1063.1562 | AB15: =V15*$Y$5 -> 963.21875 | AC15: =W15*$Y$5 -> 988.20312 | AD15: =X15*$Y$5 -> 0 | AE15: 项目进度以客户需求为主、进度不可控，交付场景按人天招标
B16: =ROW()-4 -> 12 | C16: 地面-集中式 | D16: 1+X | E16: 项目交付 | F16: 交付 | G16: 交付 | H16: SG4400UD-MV系列逆变器并网调试服务 | I16: 台 | J16: 1 | K16: 2.86 | L16: 未并网交付期间，无需办理入场 | M16: 7.22 | N16: 10.83 | O16: 9.386 | P16: 9.747 | Q16: / | S16: 1 | T16: =SUM($K16:$L16,$R16:$S16)+M16 -> 11.08 | U16: =SUM($K16:$L16,$R16:$S16)+N16 -> 14.69 | V16: =SUM($K16:$L16,$R16:$S16)+O16 -> 13.246 | W16: =SUM($K16:$L16,$R16:$S16)+P16 -> 13.607 | Y16: 81.25 | Z16: =T16*$Y$5 -> 900.25 | AA16: =U16*$Y$5 -> 1193.5625 | AB16: =V16*$Y$5 -> 1076.2375 | AC16: =W16*$Y$5 -> 1105.5687 | AD16: =X16*$Y$5 -> 0 | AE16: 项目进度以客户需求为主、进度不可控，交付场景按人天招标
B17: =ROW()-4 -> 13 | C17: 地面-集中式 | D17: 1+X | E17: 项目运维_巡检 | F17: 运维 | G17: 巡检 | H17: SG3300UD-MV系列逆变器运维服务 | I17: 台 | J17: 1 | M17: 4.75 | N17: 7.125 | O17: 6.175 | P17: 6.4125 | Q17: / | S17: 1 | T17: =SUM($K17:$L17,$R17:$S17)+M17 -> 5.75 | U17: =SUM($K17:$L17,$R17:$S17)+N17 -> 8.125 | V17: =SUM($K17:$L17,$R17:$S17)+O17 -> 7.175 | W17: =SUM($K17:$L17,$R17:$S17)+P17 -> 7.4125 | Y17: 81.25 | Z17: =T17*$Y$5 -> 467.1875 | AA17: =U17*$Y$5 -> 660.15625 | AB17: =V17*$Y$5 -> 582.96875 | AC17: =W17*$Y$5 -> 602.26562 | AD17: =X17*$Y$5 -> 0 | AE17: 巡检入场作业时间调整，存在无需开票部分
M18: =(M17+M19)/2 -> 4.915 | N18: =M18*1.5 -> 7.3725 | O18: =M18*1.3 -> 6.3895 | P18: =M18*1.35 -> 6.63525 | Q18: / | T18: =SUM($K18:$L18,$R18:$S18)+M18 -> 4.915 | U18: =SUM($K18:$L18,$R18:$S18)+N18 -> 7.3725 | V18: =SUM($K18:$L18,$R18:$S18)+O18 -> 6.3895 | W18: =SUM($K18:$L18,$R18:$S18)+P18 -> 6.63525 | Y18: 81.25 | Z18: =T18*$Y$5 -> 399.34375 | AA18: =U18*$Y$5 -> 599.01562 | AB18: =V18*$Y$5 -> 519.14688 | AC18: =W18*$Y$5 -> 539.11406 | AD18: =X18*$Y$5 -> 0 | AE18: 仅保留平均值计算
B19: =ROW()-4 -> 15 | C19: 地面-集中式 | D19: 1+X | E19: 项目运维_巡检 | F19: 运维 | G19: 巡检 | H19: SG4400UD-MV系列逆变器运维服务 | I19: 台 | J19: 1 | M19: 5.08 | N19: 7.62 | O19: 6.604 | P19: 6.858 | Q19: / | S19: 1 | T19: =SUM($K19:$L19,$R19:$S19)+M19 -> 6.08 | U19: =SUM($K19:$L19,$R19:$S19)+N19 -> 8.62 | V19: =SUM($K19:$L19,$R19:$S19)+O19 -> 7.604 | W19: =SUM($K19:$L19,$R19:$S19)+P19 -> 7.858 | Y19: 81.25 | Z19: =T19*$Y$5 -> 494 | AA19: =U19*$Y$5 -> 700.375 | AB19: =V19*$Y$5 -> 617.825 | AC19: =W19*$Y$5 -> 638.4625 | AD19: =X19*$Y$5 -> 0
B20: =ROW()-4 -> 16 | C20: 地面-集中式 | D20: 1+X | E20: 一级故障恢复 | F20: 运维 | G20: 维修 | H20: 需6个小时以上恢复的故障，具体见故障分级明细 | I20: 项 | J20: 1 | K20: 4 | L20: 4 | M20: 8 | N20: 12 | O20: 10.4 | P20: 10.8 | Q20: / | S20: 1 | T20: =SUM($K20:$L20,$R20:$S20)+M20 -> 17 | U20: =SUM($K20:$L20,$R20:$S20)+N20 -> 21 | V20: =SUM($K20:$L20,$R20:$S20)+O20 -> 19.4 | W20: =SUM($K20:$L20,$R20:$S20)+P20 -> 19.8 | Y20: 81.25 | Z20: =T20*$Y$5 -> 1381.25 | AA20: =U20*$Y$5 -> 1706.25 | AB20: =V20*$Y$5 -> 1576.25 | AC20: =W20*$Y$5 -> 1608.75 | AD20: =X20*$Y$5 -> 0 | AE20: 故障分级明细见附件1
B21: =ROW()-4 -> 17 | C21: 地面-集中式 | D21: 1+X | E21: 二级故障恢复 | F21: 运维 | G21: 维修 | H21: 6个小时内恢复的故障，具体见故障分级明细 | I21: 项 | J21: 1 | K21: 4 | L21: 4 | M21: 6 | N21: 9 | O21: 7.8 | P21: 8.1 | Q21: / | S21: 1 | T21: =SUM($K21:$L21,$R21:$S21)+M21 -> 15 | U21: =SUM($K21:$L21,$R21:$S21)+N21 -> 18 | V21: =SUM($K21:$L21,$R21:$S21)+O21 -> 16.8 | W21: =SUM($K21:$L21,$R21:$S21)+P21 -> 17.1 | Y21: 81.25 | Z21: =T21*$Y$5 -> 1218.75 | AA21: =U21*$Y$5 -> 1462.5 | AB21: =V21*$Y$5 -> 1365 | AC21: =W21*$Y$5 -> 1389.375 | AD21: =X21*$Y$5 -> 0 | AE21: 只保留此项
B22: =ROW()-4 -> 18 | C22: 地面-集中式 | D22: 1+X | E22: 三级故障恢复 | F22: 运维 | G22: 维修 | H22: 4个小时内能恢复的故障，具体见故障分级明细 | I22: 项 | J22: 1 | K22: 4 | L22: 4 | M22: 4 | N22: 6 | O22: 5.2 | P22: 5.4 | Q22: / | S22: 1 | T22: =SUM($K22:$L22,$R22:$S22)+M22 -> 13 | U22: =SUM($K22:$L22,$R22:$S22)+N22 -> 15 | V22: =SUM($K22:$L22,$R22:$S22)+O22 -> 14.2 | W22: =SUM($K22:$L22,$R22:$S22)+P22 -> 14.4 | Y22: 81.25 | Z22: =T22*$Y$5 -> 1056.25 | AA22: =U22*$Y$5 -> 1218.75 | AB22: =V22*$Y$5 -> 1153.75 | AC22: =W22*$Y$5 -> 1170 | AD22: =X22*$Y$5 -> 0
B23: =ROW()-4 -> 19 | C23: 地面-集中式 | D23: 1+X | E23: 四级故障恢复 | F23: 运维 | G23: 维修 | H23: 2个小时内能恢复的故障，具体见故障分级明细 | I23: 项 | J23: 1 | K23: 4 | L23: 4 | M23: 2 | N23: 3 | O23: 2.6 | P23: 2.7 | Q23: / | S23: 1 | T23: =SUM($K23:$L23,$R23:$S23)+M23 -> 11 | U23: =SUM($K23:$L23,$R23:$S23)+N23 -> 12 | V23: =SUM($K23:$L23,$R23:$S23)+O23 -> 11.6 | W23: =SUM($K23:$L23,$R23:$S23)+P23 -> 11.7 | Y23: 81.25 | Z23: =T23*$Y$5 -> 893.75 | AA23: =U23*$Y$5 -> 975 | AB23: =V23*$Y$5 -> 942.5 | AC23: =W23*$Y$5 -> 950.625 | AD23: =X23*$Y$5 -> 0 | AE23: 故障分级明细见附件1
B24: =ROW()-4 -> 20 | C24: 地面-集中式 | D24: SG3125 | E24: 项目运维_巡检 | F24: 运维 | G24: 巡检 | H24: SG3125HV-MV系列逆变器运维服务 | I24: 台 | J24: 1 | K24: 4 | M24: 4.915 | N24: 7.3725 | O24: 6.3895 | P24: 6.63525 | Q24: / | T24: =SUM($K24:$L24,$R24:$S24)+M24 -> 8.915 | U24: =SUM($K24:$L24,$R24:$S24)+N24 -> 11.3725 | V24: =SUM($K24:$L24,$R24:$S24)+O24 -> 10.3895 | W24: =SUM($K24:$L24,$R24:$S24)+P24 -> 10.63525 | Y24: 81.25 | Z24: =T24*$Y$5 -> 724.34375 | AA24: =U24*$Y$5 -> 924.01562 | AB24: =V24*$Y$5 -> 844.14688 | AC24: =W24*$Y$5 -> 864.11406 | AD24: =X24*$Y$5 -> 0 | AE24: 3125巡检工时与1+X一致
B25: =ROW()-4 -> 21 | C25: 地面-集中式 | D25: SG3125 | E25: 二级故障恢复 | F25: 运维 | G25: 维修 | H25: 6个小时内恢复的故障，具体见故障分级明细 | I25: 项 | J25: 1 | K25: 4 | L25: 4 | M25: 6 | N25: 8.1 | O25: 7.8 | P25: 9 | Q25: / | S25: 1 | T25: =SUM($K25:$L25,$R25:$S25)+M25 -> 15 | U25: =SUM($K25:$L25,$R25:$S25)+N25 -> 17.1 | V25: =SUM($K25:$L25,$R25:$S25)+O25 -> 16.8 | W25: =SUM($K25:$L25,$R25:$S25)+P25 -> 18 | Y25: 81.25 | Z25: =T25*$Y$5 -> 1218.75 | AA25: =U25*$Y$5 -> 1389.375 | AB25: =V25*$Y$5 -> 1365 | AC25: =W25*$Y$5 -> 1462.5 | AD25: =X25*$Y$5 -> 0 | AE25: 逆变器不在岸边，定义为水上光伏 只保留此项，入场办理+故障处理最高8H 吊车+叉车单独申请
B26: =ROW()-4 -> 22 | C26: 储能 | D26: PT2.0HX | E26: 设备到货检查及安装_交付 | F26: 交付 | G26: 交付 | H26: 设备到货检查、MSD安装、贴膜移除等 | I26: MWH | J26: 1 | K26: 2.86 | L26: 未并网交付期间，无需办理入场 | M26: 0.9 | N26: / | O26: / | P26: 1.215 | Q26: / | S26: 1 | T26: =SUM($K26:$L26,$R26:$S26)+M26 -> 4.76 | W26: =SUM($K26:$L26,$R26:$S26)+P26 -> 5.075 | Y26: 81.25 | Z26: =T26*$Y$5 -> 386.75 | AA26: =U26*$Y$5 -> 0 | AB26: =V26*$Y$5 -> 0 | AC26: =W26*$Y$5 -> 412.34375 | AD26: =X26*$Y$5 -> 0 | AE26: 项目进度以客户需求为主、进度不可控，交付场景按人天招标 | AF26: 储能所有服务场景，基于服务能力，按人天招标
B27: =ROW()-4 -> 23 | C27: 储能 | D27: PT2.0HX | E27: 冷调检查_交付 | F27: 交付 | G27: 交付 | H27: 设备冷调及现场接线检查 | I27: MWH | J27: 1 | K27: 2.86 | L27: 未并网交付期间，无需办理入场 | M27: 0.78 | N27: / | O27: / | P27: 1.053 | Q27: / | S27: 1 | T27: =SUM($K27:$L27,$R27:$S27)+M27 -> 4.64 | W27: =SUM($K27:$L27,$R27:$S27)+P27 -> 4.913 | Y27: 81.25 | Z27: =T27*$Y$5 -> 377 | AA27: =U27*$Y$5 -> 0 | AB27: =V27*$Y$5 -> 0 | AC27: =W27*$Y$5 -> 399.18125 | AD27: =X27*$Y$5 -> 0 | AE27: 项目进度以客户需求为主、进度不可控，交付场景按人天招标
B28: =ROW()-4 -> 24 | C28: 储能 | D28: PT2.0HX | E28: 系统通讯调试_交付 | F28: 交付 | G28: 交付 | H28: 系统IP配置，通讯调试 | I28: MWH | J28: 1 | K28: 2.86 | L28: 未并网交付期间，无需办理入场 | M28: 1 | N28: / | O28: / | P28: 1.35 | Q28: / | S28: 1 | T28: =SUM($K28:$L28,$R28:$S28)+M28 -> 4.86 | W28: =SUM($K28:$L28,$R28:$S28)+P28 -> 5.21 | Y28: 81.25 | Z28: =T28*$Y$5 -> 394.875 | AA28: =U28*$Y$5 -> 0 | AB28: =V28*$Y$5 -> 0 | AC28: =W28*$Y$5 -> 423.3125 | AD28: =X28*$Y$5 -> 0 | AE28: 项目进度以客户需求为主、进度不可控，交付场景按人天招标
B29: =ROW()-4 -> 25 | C29: 储能 | D29: PT2.0HX | E29: 系统上电_交付 | F29: 交付 | G29: 交付 | H29: 系统上电 | I29: MWH | J29: 1 | K29: 2.86 | L29: 未并网交付期间，无需办理入场 | M29: 0.4 | N29: / | O29: / | P29: 0.54 | Q29: / | S29: 1 | T29: =SUM($K29:$L29,$R29:$S29)+M29 -> 4.26 | W29: =SUM($K29:$L29,$R29:$S29)+P29 -> 4.4 | Y29: 81.25 | Z29: =T29*$Y$5 -> 346.125 | AA29: =U29*$Y$5 -> 0 | AB29: =V29*$Y$5 -> 0 | AC29: =W29*$Y$5 -> 357.5 | AD29: =X29*$Y$5 -> 0 | AE29: 项目进度以客户需求为主、进度不可控，交付场景按人天招标
B30: =ROW()-4 -> 26 | C30: 储能 | D30: PT2.0HX | E30: 单元级热调_交付 | F30: 交付 | G30: 交付 | H30: 单元级性能调试 | I30: MWH | J30: 1 | K30: 2.86 | L30: 未并网交付期间，无需办理入场 | M30: 0.46 | N30: / | O30: / | P30: 0.621 | Q30: / | S30: 1 | T30: =SUM($K30:$L30,$R30:$S30)+M30 -> 4.32 | W30: =SUM($K30:$L30,$R30:$S30)+P30 -> 4.481 | Y30: 81.25 | Z30: =T30*$Y$5 -> 351 | AA30: =U30*$Y$5 -> 0 | AB30: =V30*$Y$5 -> 0 | AC30: =W30*$Y$5 -> 364.08125 | AD30: =X30*$Y$5 -> 0 | AE30: 项目进度以客户需求为主、进度不可控，交付场景按人天招标
B31: =ROW()-4 -> 27 | C31: 储能 | D31: PT2.0HX | E31: 系统热调_交付 | F31: 交付 | G31: 交付 | H31: 系统性能调试 | I31: 站 | J31: 1 | K31: 2.86 | L31: 未并网交付期间，无需办理入场 | M31: 76.25 | N31: / | O31: / | P31: 102.9375 | Q31: / | S31: 1 | T31: =SUM($K31:$L31,$R31:$S31)+M31 -> 80.11 | W31: =SUM($K31:$L31,$R31:$S31)+P31 -> 106.7975 | Y31: 81.25 | Z31: =T31*$Y$5 -> 6508.9375 | AA31: =U31*$Y$5 -> 0 | AB31: =V31*$Y$5 -> 0 | AC31: =W31*$Y$5 -> 8677.2969 | AD31: =X31*$Y$5 -> 0 | AE31: 项目进度以客户需求为主、进度不可控，交付场景按人天招标
B32: =ROW()-4 -> 28 | C32: 储能 | D32: PT2.0HX | E32: 预防性维护_巡检 | F32: 运维 | G32: 巡检 | H32: 电池箱运维 | I32: 台/年 | J32: 1 | K32: 2.86 | L32: 4 | M32: 16.266667 | N32: / | O32: / | P32: 21.96 | Q32: / | S32: 1 | T32: =SUM($K32:$L32,$R32:$S32)+M32 -> 24.126667 | W32: =SUM($K32:$L32,$R32:$S32)+P32 -> 29.82 | Y32: 81.25 | Z32: =T32*$Y$5 -> 1960.2917 | AA32: =U32*$Y$5 -> 0 | AB32: =V32*$Y$5 -> 0 | AC32: =W32*$Y$5 -> 2422.875 | AD32: =X32*$Y$5 -> 0 | AE32: 计量单位为台/年耗时，需统计巡检频次，折算为单台单次耗时 | AF32: 巡检出具宽泛版、无需断电
B33: =ROW()-4 -> 29 | C33: 储能 | D33: PT2.0HX | E33: 预防性维护_巡检 | F33: 运维 | G33: 巡检 | H33: PCS运维项目合计 | I33: 台/年 | J33: 1 | K33: 2.86 | L33: 4 | M33: 3.37 | N33: / | O33: / | P33: 4.5495 | Q33: / | S33: 1 | T33: =SUM($K33:$L33,$R33:$S33)+M33 -> 11.23 | W33: =SUM($K33:$L33,$R33:$S33)+P33 -> 12.4095 | Y33: 81.25 | Z33: =T33*$Y$5 -> 912.4375 | AA33: =U33*$Y$5 -> 0 | AB33: =V33*$Y$5 -> 0 | AC33: =W33*$Y$5 -> 1008.2719 | AD33: =X33*$Y$5 -> 0 | AE33: 计量单位为台/年耗时，需统计巡检频次，折算为单台单次耗时
B34: =ROW()-4 -> 30 | C34: 储能 | D34: PT2.0HX | E34: 预防性维护_巡检 | F34: 运维 | G34: 巡检 | H34: MVS运维项目 | I34: 台/年 | J34: 1 | K34: 2.86 | L34: 4 | M34: 19.083333 | N34: / | O34: / | P34: 25.7625 | Q34: / | S34: 1 | T34: =SUM($K34:$L34,$R34:$S34)+M34 -> 26.943333 | W34: =SUM($K34:$L34,$R34:$S34)+P34 -> 33.6225 | Y34: 81.25 | Z34: =T34*$Y$5 -> 2189.1458 | AA34: =U34*$Y$5 -> 0 | AB34: =V34*$Y$5 -> 0 | AC34: =W34*$Y$5 -> 2731.8281 | AD34: =X34*$Y$5 -> 0 | AE34: 计量单位为台/年耗时，需统计巡检频次，折算为单台单次耗时
B35: =ROW()-4 -> 31 | C35: 储能 | D35: PT2.0HX | E35: 部件更换_维修 | F35: 运维 | G35: 维修 | H35: 系统主要部件更换 | I35: PCS | J35: 见部件更换清单 | K35: 2.86 | L35: 4 | M35: 见部件更换清单 | S35: 1 | T35: =SUM($K35:$L35,$R35:$S35)+M35 -> #VALUE! | W35: =SUM($K35:$L35,$R35:$S35)+P35 -> 7.86 | Y35: 81.25 | Z35: =T35*$Y$5 -> #VALUE! | AA35: =U35*$Y$5 -> 0 | AB35: =V35*$Y$5 -> 0 | AC35: =W35*$Y$5 -> 638.625 | AD35: =X35*$Y$5 -> 0 | AE35: 见附件2
B36: =ROW()-4 -> 32 | C36: 储能 | D36: PT2.0UD | E36: 设备到货检查及安装_交付 | F36: 交付 | G36: 交付 | H36: 设备到货检查、MSD安装、贴膜移除等 | I36: MWH | J36: 1 | K36: 2.86 | L36: 未并网交付期间，无需办理入场 | M36: 0.9 | N36: / | O36: / | P36: 1.215 | Q36: / | S36: 1 | T36: =SUM($K36:$L36,$R36:$S36)+M36 -> 4.76 | W36: =SUM($K36:$L36,$R36:$S36)+P36 -> 5.075 | Y36: 81.25 | Z36: =T36*$Y$5 -> 386.75 | AA36: =U36*$Y$5 -> 0 | AB36: =V36*$Y$5 -> 0 | AC36: =W36*$Y$5 -> 412.34375 | AD36: =X36*$Y$5 -> 0 | AE36: 项目进度以客户需求为主、进度不可控，交付场景按人天招标
B37: =ROW()-4 -> 33 | C37: 储能 | D37: PT2.0UD | E37: 冷调检查_交付 | F37: 交付 | G37: 交付 | H37: 设备冷调及现场接线检查 | I37: MWH | J37: 1 | K37: 2.86 | L37: 未并网交付期间，无需办理入场 | M37: 0.78 | N37: / | O37: / | P37: 1.053 | Q37: / | S37: 1 | T37: =SUM($K37:$L37,$R37:$S37)+M37 -> 4.64 | W37: =SUM($K37:$L37,$R37:$S37)+P37 -> 4.913 | Y37: 81.25 | Z37: =T37*$Y$5 -> 377 | AA37: =U37*$Y$5 -> 0 | AB37: =V37*$Y$5 -> 0 | AC37: =W37*$Y$5 -> 399.18125 | AD37: =X37*$Y$5 -> 0 | AE37: 项目进度以客户需求为主、进度不可控，交付场景按人天招标
B38: =ROW()-4 -> 34 | C38: 储能 | D38: PT2.0UD | E38: 系统通讯调试_交付 | F38: 交付 | G38: 交付 | H38: 系统IP配置，通讯调试 | I38: MWH | J38: 1 | K38: 2.86 | L38: 未并网交付期间，无需办理入场 | M38: 0.9 | N38: / | O38: / | P38: 1.215 | Q38: / | S38: 1 | T38: =SUM($K38:$L38,$R38:$S38)+M38 -> 4.76 | W38: =SUM($K38:$L38,$R38:$S38)+P38 -> 5.075 | Y38: 81.25 | Z38: =T38*$Y$5 -> 386.75 | AA38: =U38*$Y$5 -> 0 | AB38: =V38*$Y$5 -> 0 | AC38: =W38*$Y$5 -> 412.34375 | AD38: =X38*$Y$5 -> 0 | AE38: 项目进度以客户需求为主、进度不可控，交付场景按人天招标
B39: =ROW()-4 -> 35 | C39: 储能 | D39: PT2.0UD | E39: 系统上电_交付 | F39: 交付 | G39: 交付 | H39: 系统上电 | I39: MWH | J39: 1 | K39: 2.86 | L39: 未并网交付期间，无需办理入场 | M39: 0.4 | N39: / | O39: / | P39: 0.54 | Q39: / | S39: 1 | T39: =SUM($K39:$L39,$R39:$S39)+M39 -> 4.26 | W39: =SUM($K39:$L39,$R39:$S39)+P39 -> 4.4 | Y39: 81.25 | Z39: =T39*$Y$5 -> 346.125 | AA39: =U39*$Y$5 -> 0 | AB39: =V39*$Y$5 -> 0 | AC39: =W39*$Y$5 -> 357.5 | AD39: =X39*$Y$5 -> 0 | AE39: 项目进度以客户需求为主、进度不可控，交付场景按人天招标
B40: =ROW()-4 -> 36 | C40: 储能 | D40: PT2.0UD | E40: 单元级热调_交付 | F40: 交付 | G40: 交付 | H40: 单元级性能调试 | I40: MWH | J40: 1 | K40: 2.86 | L40: 未并网交付期间，无需办理入场 | M40: 0.46 | N40: / | O40: / | P40: 0.621 | Q40: / | S40: 1 | T40: =SUM($K40:$L40,$R40:$S40)+M40 -> 4.32 | W40: =SUM($K40:$L40,$R40:$S40)+P40 -> 4.481 | Y40: 81.25 | Z40: =T40*$Y$5 -> 351 | AA40: =U40*$Y$5 -> 0 | AB40: =V40*$Y$5 -> 0 | AC40: =W40*$Y$5 -> 364.08125 | AD40: =X40*$Y$5 -> 0 | AE40: 项目进度以客户需求为主、进度不可控，交付场景按人天招标
B41: =ROW()-4 -> 37 | C41: 储能 | D41: PT2.0UD | E41: 系统热调_交付 | F41: 交付 | G41: 交付 | H41: 系统性能调试 | I41: 站 | J41: 1 | K41: 2.86 | L41: 未并网交付期间，无需办理入场 | M41: 76.25 | N41: / | O41: / | P41: 102.9375 | Q41: / | S41: 1 | T41: =SUM($K41:$L41,$R41:$S41)+M41 -> 80.11 | W41: =SUM($K41:$L41,$R41:$S41)+P41 -> 106.7975 | Y41: 81.25 | Z41: =T41*$Y$5 -> 6508.9375 | AA41: =U41*$Y$5 -> 0 | AB41: =V41*$Y$5 -> 0 | AC41: =W41*$Y$5 -> 8677.2969 | AD41: =X41*$Y$5 -> 0 | AE41: 项目进度以客户需求为主、进度不可控，交付场景按人天招标
...

Sheet 储能系统更换部件及耗时
B2: 密级：重要
B3: 附件2：PT2.0系统主要器件更换工时清单
B4: 产品类别 Product Category | C4: 系统类别 System Category | D4: 器件位置 Component Location | E4: 推荐作业工时合计 | F4: 备注 Remarks | G4: 不含作业工时在内的综合工时 （在途、入场办理、离场交接，不区分业务场景） | H4: 综合工时 （在途、入场办理、维修作业、离场交接全流程）
B5: PT2.0-HX | C5: ESS | D5: 注排液 | E5: 9.5 | G5: ='服务BOQ（含在途、入场、现场服务工时、离场交接）'!$T$35 -> #VALUE! | H5: =G5+E5 -> #VALUE!
B6: PT2.0-HX | C6: ESS | D6: MSD | E6: 1.7 | G6: ='服务BOQ（含在途、入场、现场服务工时、离场交接）'!$T$35 -> #VALUE! | H6: =G6+E6 -> #VALUE!
B7: PT2.0-HX | C7: ESS | D7: PACK更换 | E7: 19 | G7: ='服务BOQ（含在途、入场、现场服务工时、离场交接）'!$T$35 -> #VALUE! | H7: =G7+E7 -> #VALUE!
B8: PT2.0-HX | C8: ESS | D8: BMU | E8: 3.5 | G8: ='服务BOQ（含在途、入场、现场服务工时、离场交接）'!$T$35 -> #VALUE! | H8: =G8+E8 -> #VALUE!
B9: PT2.0-HX | C9: ESS | D9: PCS熔丝盒 | E9: 5.5 | G9: ='服务BOQ（含在途、入场、现场服务工时、离场交接）'!$T$35 -> #VALUE! | H9: =G9+E9 -> #VALUE!
B10: PT2.0-HX | C10: ESS | D10: PCS | E10: 11.25 | G10: ='服务BOQ（含在途、入场、现场服务工时、离场交接）'!$T$35 -> #VALUE! | H10: =G10+E10 -> #VALUE!
B11: PT2.0-HX | C11: ESS | D11: PCS 风盘 | E11: 1.25 | G11: ='服务BOQ（含在途、入场、现场服务工时、离场交接）'!$T$35 -> #VALUE! | H11: =G11+E11 -> #VALUE!
B12: PT2.0-HX | C12: ESS | D12: 单PACK补电 | E12: 1.5 | F12: 视PACK欠压状态而定，SOC每偏差1%，需补电0.15H | G12: ='服务BOQ（含在途、入场、现场服务工时、离场交接）'!$T$35 -> #VALUE! | H12: =G12+E12 -> #VALUE!
B13: PT2.0-HX | C13: ESS | D13: 电芯均衡 | E13: 0.75 | F13: 视单电芯欠压状态而定，SOC每偏差1%，需补电3.5H | G13: ='服务BOQ（含在途、入场、现场服务工时、离场交接）'!$T$35 -> #VALUE! | H13: =G13+E13 -> #VALUE!
B14: PT2.0-HX | C14: ESS | D14: 烟感 | E14: 1.7 | G14: ='服务BOQ（含在途、入场、现场服务工时、离场交接）'!$T$35 -> #VALUE! | H14: =G14+E14 -> #VALUE!
B15: PT2.0-HX | C15: ESS | D15: 温感 | E15: 1.7 | G15: ='服务BOQ（含在途、入场、现场服务工时、离场交接）'!$T$35 -> #VALUE! | H15: =G15+E15 -> #VALUE!
B16: PT2.0-HX | C16: ESS | D16: 气体探测器 | E16: 2.5 | G16: ='服务BOQ（含在途、入场、现场服务工时、离场交接）'!$T$35 -> #VALUE! | H16: =G16+E16 -> #VALUE!
B17: PT2.0-HX | C17: ESS | D17: 门禁 | E17: 2 | G17: ='服务BOQ（含在途、入场、现场服务工时、离场交接）'!$T$35 -> #VALUE! | H17: =G17+E17 -> #VALUE!
B18: PT2.0-HX | C18: ESS | D18: 消防钢瓶 | E18: 3.5 | G18: ='服务BOQ（含在途、入场、现场服务工时、离场交接）'!$T$35 -> #VALUE! | H18: =G18+E18 -> #VALUE!
B19: PT2.0-HX | C19: ESS | D19: 簇间熔断器 | E19: 2.5 | G19: ='服务BOQ（含在途、入场、现场服务工时、离场交接）'!$T$35 -> #VALUE! | H19: =G19+E19 -> #VALUE!
B20: PT2.0-HX | C20: ESS | D20: 气溶胶 | E20: 1.25 | G20: ='服务BOQ（含在途、入场、现场服务工时、离场交接）'!$T$35 -> #VALUE! | H20: =G20+E20 -> #VALUE!
B21: PT2.0-HX | C21: ESS | D21: 液冷机组 | E21: 46.5 | G21: ='服务BOQ（含在途、入场、现场服务工时、离场交接）'!$T$35 -> #VALUE! | H21: =G21+E21 -> #VALUE!
B22: PT2.0-HX | C22: ESS | D22: 八通阀 | E22: 31 | G22: ='服务BOQ（含在途、入场、现场服务工时、离场交接）'!$T$35 -> #VALUE! | H22: =G22+E22 -> #VALUE!
B23: PT2.0-HX | C23: ESS | D23: 电源模块 | E23: 1.5 | G23: ='服务BOQ（含在途、入场、现场服务工时、离场交接）'!$T$35 -> #VALUE! | H23: =G23+E23 -> #VALUE!
B24: PT2.0-HX | C24: ESS | D24: 消防防雷器 | E24: 1 | G24: ='服务BOQ（含在途、入场、现场服务工时、离场交接）'!$T$35 -> #VALUE! | H24: =G24+E24 -> #VALUE!
B25: PT2.0-HX | C25: ESS | D25: 继电器 | E25: 1.25 | G25: ='服务BOQ（含在途、入场、现场服务工时、离场交接）'!$T$35 -> #VALUE! | H25: =G25+E25 -> #VALUE!
... B66: PT2.0-HX | C66: MVS | D66: 主断路器 | E66: 12 | G66: ='服务BOQ（含在途、入场、现场服务工时、离场交接）'!$T$35 -> #VALUE! | H66: =G66+E66 -> #VALUE!
B67: PT2.0-HX | C67: MVS | D67: 升压变压器 | E67: 8 | F67: 更换4人8小时，交接试验及配合送电1人8小时,国内厂家配合更换 | G67: ='服务BOQ（含在途、入场、现场服务工时、离场交接）'!$T$35 -> #VALUE! | H67: =G67+E67 -> #VALUE!
B68: PT2.0-HX | C68: MVS | D68: 环网柜 | E68: 32 | G68: ='服务BOQ（含在途、入场、现场服务工时、离场交接）'!$T$35 -> #VALUE! | H68: =G68+E68 -> #VALUE!
B69: PT2.0-HX | C69: ESS | D69: 安全上下电 | E69: 2 | G69: ='服务BOQ（含在途、入场、现场服务工时、离场交接）'!$T$35 -> #VALUE! | H69: =G69+E69 -> #VALUE!
B70: PT2.0-HX | C70: ESS | D70: 注排液 | E70: 9.5 | G70: ='服务BOQ（含在途、入场、现场服务工时、离场交接）'!$T$35 -> #VALUE! | H70: =G70+E70 -> #VALUE!
B71: PT2.0-HX | C71: ESS | D71: MSD | E71: 1.7 | G71: ='服务BOQ（含在途、入场、现场服务工时、离场交接）'!$T$35 -> #VALUE! | H71: =G71+E71 -> #VALUE!
B72: PT2.0-HX | C72: ESS | D72: PACK更换 | E72: 19 | G72: ='服务BOQ（含在途、入场、现场服务工时、离场交接）'!$T$35 -> #VALUE! | H72: =G72+E72 -> #VALUE!
B73: PT2.0-HX | C73: ESS | D73: BMU | E73: 3.5 | G73: ='服务BOQ（含在途、入场、现场服务工时、离场交接）'!$T$35 -> #VALUE! | H73: =G73+E73 -> #VALUE!
B74: PT2.0-HX | C74: ESS | D74: PCS熔丝盒 | E74: 5.5 | G74: ='服务BOQ（含在途、入场、现场服务工时、离场交接）'!$T$35 -> #VALUE! | H74: =G74+E74 -> #VALUE!
B75: PT2.0-HX | C75: ESS | D75: PCS | E75: 11.25 | G75: ='服务BOQ（含在途、入场、现场服务工时、离场交接）'!$T$35 -> #VALUE! | H75: =G75+E75 -> #VALUE!
B76: PT2.0-HX | C76: ESS | D76: PCS 风盘 | E76: 16 | F76: 视PACK欠压状态而定，SOC每偏差1%，需补电0.15H | G76: ='服务BOQ（含在途、入场、现场服务工时、离场交接）'!$T$35 -> #VALUE! | H76: =G76+E76 -> #VALUE!
B77: PT2.0-HX | C77: ESS | D77: 单PACK补电 | E77: 24 | F77: 视单电芯欠压状态而定，SOC每偏差1%，需补电3.5H | G77: ='服务BOQ（含在途、入场、现场服务工时、离场交接）'!$T$35 -> #VALUE! | H77: =G77+E77 -> #VALUE!
B78: PT2.0-HX | C78: ESS | D78: 电芯均衡 | E78: 0.75 | G78: ='服务BOQ（含在途、入场、现场服务工时、离场交接）'!$T$35 -> #VALUE! | H78: =G78+E78 -> #VALUE!
B79: PT2.0-HX | C79: ESS | D79: 烟感 | E79: 1.7 | G79: ='服务BOQ（含在途、入场、现场服务工时、离场交接）'!$T$35 -> #VALUE! | H79: =G79+E79 -> #VALUE!
B80: PT2.0-HX | C80: ESS | D80: 温感 | E80: 1.7 | G80: ='服务BOQ（含在途、入场、现场服务工时、离场交接）'!$T$35 -> #VALUE! | H80: =G80+E80 -> #VALUE!
B81: PT2.0-HX | C81: ESS | D81: 气体探测器 | E81: 2.5 | G81: ='服务BOQ（含在途、入场、现场服务工时、离场交接）'!$T$35 -> #VALUE! | H81: =G81+E81 -> #VALUE!
...
